Workbook

Sheet Hoja1
B2: Plato | C2: Tiempo | D2: Valor | E2: Region | F2: Pais | G2: Tipo | H2: Ingrediente | I2: Estilo
B3: Paella
B4: Pizza
B5: Burger
B6: Falafel | M6: Maki | N6: Sushi · Arroz · Pescado · Frío · Japonés
B7: Sopa | M7: Temaki | N7: Sushi · Arroz · Pescado · Frío · Japonés
B8: Sandwich | M8: Onigiri | N8: Arroz · Frío · Japonés
B9: Taco | M9: Sashimi | N9: Sushi · Pescado · Frío · Japonés
B10: Ensalada
B11: Macarrones
B12: Espaguetis
B13: Gazpacho
B14: Albondigas
B15: Calçots
B16: Burritos
B17: Kebab
B18: Durum
B19: Palta
B20: Nigiri
B21: Maki
... B117: Crabcake

Sheet chat gpt
A1: Comun | B1: Poco comun | C1: Raros | D1: Epicos | E1: Legendarios
A2: Pizza margarita | B2: Paella | C2: Ceviche | D2: Beef Wellington | E2: Filete de Wagyu
A3: Hamburguesa | B3: Tortilla de patatas | C3: Ají de gallina | D3: Coq au vin | E3: Wagyu A5
A4: Hot dog | B4: Gazpacho | C4: Lomo saltado | D4: Foie gras | E4: Fugu
A5: Sándwich mixto | B5: Gambas al ajillo | C5: Anticuchos | D5: Lobster roll | E5: Caviar Beluga
A6: Bocadillo | B6: Pulpo a la gallega | C6: Pachamanca | D6: Bogavante a la parrilla | E6: Trufa blanca con pasta | I6: Arroces | K6: Pasta y fideos
A7: Ensalada mixta | B7: Patatas bravas | C7: Rocoto relleno | D7: Centollo | E7: Trufa negra con risotto
A8: Sopa de verduras | B8: Calçots | C8: Pozole | D8: Percebes | E8: Langosta Thermidor | I8: 1. Paella valenciana | K8: 11. Espaguetis carbonara
A9: Espaguetis con tomate | B9: Fideuà | C9: Mole poblano | D9: Caviar | E9: Pato Pekín imperial | I9: 2. Paella de marisco | K9: 12. Lasaña
A10: Macarrones con queso | B10: Cachopo | C10: Chiles rellenos | D10: Steak tartare | E10: Sushi Omakase | I10: 3. Risotto | K10: 13. Ravioli
A11: Tortilla francesa | B11: Fabada | C11: Chilaquiles | D11: Carpaccio | E11: Kobe steak | I11: 4. Arroz frito chino | K11: 14. Gnocchi
A12: Huevo frito | B12: Risotto | C12: Birria | D12: Ossobuco | E12: Paella imperial de marisco | I12: 5. Biryani | K12: 15. Macarrones con queso
A13: Patatas fritas | B13: Carbonara | C13: Cochinita pibil | D13: Bistecca alla Fiorentina | E13: Wellington de Wagyu | I13: 6. Nasi goreng | K13: 16. Ramen
A14: Aros de cebolla | B14: Ravioli | C14: Bandeja paisa | D14: Porchetta | E14: Foie gras con trufa | I14: 7. Bibimbap | K14: 17. Udon
A15: Nuggets de pollo | B15: Gnocchi | C15: Ajiaco | D15: Pato a la naranja | E15: Centollo real | I15: 8. Jambalaya | K15: 18. Soba
A16: Alitas de pollo | B16: Calzone | C16: Sancocho | D16: Costillar BBQ | E16: King crab | I16: 9. Arroz con pollo | K16: 19. Pad thai
A17: Pollo asado | B17: Parmigiana | C17: Patacón | D17: Pulled pork | E17: Atún rojo Otoro | I17: 10. Kabsa | K17: 20. Pho
A18: Arroz blanco | B18: Arancini | C18: Feijoada | D18: Brisket | E18: Chawanmushi premium
A19: Arroz frito | B19: Focaccia | C19: Moqueca | D19: Gumbo | E19: Bouillabaisse real
A20: Curry con arroz | B20: Ratatouille | C20: Coxinha | D20: Jambalaya | E20: Lechón entero
A21: Taco | B21: Sopa de cebolla | C21: Acarajé | D21: Crab cake | E21: Banquete Kaiseki | I21: Pizza, panes planos y masas | K21: Bocadillos, wraps y comida entre pan
A22: Burrito | B22: Croque monsieur | C22: Asado argentino | D22: Surf and turf
A23: Quesadilla | B23: Cassoulet | C23: Milanesa | D23: Chile en nogada | I23: 21. Pizza margarita | K23: 31. Hamburguesa
A24: Nachos | B24: Escargots | C24: Provoleta | D24: Lechón | I24: 22. Pizza pepperoni | K24: 32. Cheeseburger
A25: Empanada | B25: Shepherd's pie | C25: Choripán | D25: Cabrito asado | I25: 23. Calzone | K25: 33. Hot dog
A26: Arepa | B26: Bangers and mash | C26: Francesinha | D26: Rendang | I26: 24. Focaccia | K26: 34. Bánh mì
A27: Falafel | B27: Schnitzel | C27: Bacalhau à brás | D27: Butter chicken | I27: 25. Lahmacun | K27: 35. Kebab dürüm
A28: Kebab | B28: Currywurst | C28: Pastel de bacalao | D28: Biryani | I28: 26. Manakish | K28: 36. Shawarma
A29: Hummus | B29: Bratwurst | C29: Alheira | D29: Tandoori chicken | I29: 27. Flammkuchen | K29: 37. Gyros
A30: Cuscús | B30: Goulash | C30: Beef bourguignon | D30: Rogan josh | I30: 28. Pide turco | K30: 38. Choripán
A31: Croquetas | B31: Pierogi | C31: Duck confit | D31: Dosa masala | I31: 29. Khachapuri | K31: 39. Francesinha
A32: Calamares fritos | B32: Żurek | C32: Bouillabaisse | D32: Palak paneer | I32: 30. Okonomiyaki | K32: 40. Lobster roll
A33: Mejillones | B33: Souvlaki | C33: Beef stroganoff | D33: Peking duck completo
A34: Fish and chips | B34: Moussaka | C34: Wiener schnitzel | D34: Korean BBQ
A35: Ramen básico | B35: Gyros | C35: Raclette | D35: Sashimi premium
A36: Udon | B36: Dolma | C36: Fondue | D36: Chirashi sushi | I36: Tacos y comida mexicana | K36: Sopas y caldos
A37: Soba | B37: Köfte | C37: Smørrebrød | D37: Unagi kabayaki
A38: Onigiri | B38: Shakshuka | C38: Peking duck | D38: Kaiseki | I38: 41. Taco al pastor | K38: 51. Gazpacho
A39: Gyoza | B39: Tajine | C39: Hot pot | D39: Tomahawk steak | I39: 42. Taco de pescado | K39: 52. Sopa de cebolla
A40: Maki | B40: Shawarma | C40: Xiaolongbao | D40: Cordero asado | I40: 43. Burrito | K40: 53. Sopa de miso
...

Sheet bebida chatgpt
A1: Café | C1: Té | E1: Cócteles | G1: Cócteles sin alcohol | I1: Zumos | K1: Batidos | M1: Smoothies | O1: Refrescos y bebidas frías | Q1: Bebidas premium
A3: 1. Espresso | C3: 21. Té verde | E3: 41. Mojito | G3: 71. Virgin Mojito | I3: 81. Zumo de naranja | K3: 101. Batido de chocolate | M3: 121. Smoothie de fresa y plátano | O3: 131. Cola | Q3: 151. Champagne
A4: 2. Doble espresso | C4: 22. Té negro | E4: 42. Margarita | G4: 72. Shirley Temple | I4: 82. Zumo de manzana | K4: 102. Batido de vainilla | M4: 122. Smoothie de mango | O4: 132. Cola de cereza | Q4: 152. Prosecco
A5: 3. Americano | C5: 23. Té blanco | E5: 43. Daiquiri | G5: 73. Virgin Piña Colada | I5: 83. Zumo de piña | K5: 103. Batido de fresa | M5: 123. Smoothie verde | O5: 133. Limonada | Q5: 153. Vino tinto
A6: 4. Cappuccino | C6: 24. Té rojo | E6: 44. Piña colada | G6: 74. Fruit Punch | I6: 84. Zumo de mango | K6: 104. Batido de plátano | M6: 124. Smoothie tropical | O6: 134. Limonada rosa | Q6: 154. Vino blanco
A7: 5. Latte | C7: 25. Té oolong | E7: 45. Caipirinha | G7: 75. Lemon Fizz | I7: 85. Zumo de sandía | K7: 105. Batido de mango | M7: 125. Smoothie de frutos rojos | O7: 135. Naranjada | Q7: 155. Vino rosado
A8: 6. Flat white | C8: 26. Té matcha | E8: 46. Cosmopolitan | G8: 76. Ginger Fizz | I8: 86. Zumo de uva | K8: 106. Batido de Oreo | M8: 126. Smoothie de piña y coco | O8: 136. Ginger ale | Q8: 156. Sake
A9: 7. Macchiato | C9: 27. Chai masala | E9: 47. Negroni | G9: 77. Tropical Cooler | I9: 87. Zumo de granada | K9: 107. Batido de caramelo | M9: 127. Smoothie de aguacate | O9: 137. Ginger beer | Q9: 157. Soju
A10: 8. Mocha | C10: 28. Earl Grey | E10: 48. Old Fashioned | G10: 78. Cucumber Cooler | I10: 88. Zumo de melocotón | K10: 108. Batido de café | M10: 128. Smoothie de açai | O10: 138. Root beer | Q10: 158. Umeshu
A11: 9. Café bombón | C11: 29. English breakfast tea | E11: 49. Manhattan | G11: 79. Berry Spritz | I11: 89. Zumo de pera | K11: 109. Batido de coco | M11: 129. Smoothie de melocotón | O11: 139. Cream soda | Q11: 159. Sangría
A12: 10. Café con leche | C12: 30. Té de jazmín | E12: 50. Martini | G12: 80. Citrus Spritz | I12: 90. Zumo de tomate | K12: 110. Batido de frutos rojos | M12: 130. Smoothie de kiwi | O12: 140. Agua con gas | Q12: 160. Vermut
A13: 11. Café cortado | C13: 31. Té de menta | E13: 51. Dry Martini | I13: 91. Zumo de zanahoria | K13: 111. Batido de pistacho | O13: 141. Tónica
A14: 12. Affogato | C14: 32. Té de hibisco | E14: 52. Espresso Martini | I14: 92. Zumo de remolacha | K14: 112. Batido de matcha | O14: 142. Horchata
A15: 13. Cold brew | C15: 33. Té de limón | E15: 53. Moscow Mule | I15: 93. Zumo de limón | K15: 113. Batido de peanut butter | O15: 143. Agua de jamaica
A16: 14. Iced latte | C16: 34. Té de jengibre | E16: 54. Bloody Mary | I16: 94. Zumo de lima | K16: 114. Batido de cookies | O16: 144. Agua de tamarindo
A17: 15. Frappé | C17: 35. Bubble tea | E17: 55. Mai Tai | I17: 95. Zumo tropical | K17: 115. Batido tropical | O17: 145. Agua de coco
A18: 16. Café turco | C18: 36. Thai tea | E18: 56. Long Island Iced Tea | I18: 96. Zumo de frutos rojos | K18: 116. Batido de aguacate | O18: 146. Ayran
A19: 17. Café vietnamita | C19: 37. Té marroquí | E19: 57. Tequila Sunrise | I19: 97. Zumo verde | K19: 117. Batido de dátiles | O19: 147. Lassi
A20: 18. Café irlandés | C20: 38. Té turco | E20: 58. Sex on the Beach | I20: 98. Zumo de papaya | K20: 118. Batido de taro | O20: 148. Mango lassi
A21: 19. Café de olla | C21: 39. Té helado | E21: 59. Aperol Spritz | I21: 99. Zumo de guayaba | K21: 119. Batido de ube | O21: 149. Doogh
A22: 20. Café dalgona | C22: 40. Genmaicha | E22: 60. Cuba Libre | I22: 100. Zumo de maracuyá | K22: 120. Batido de sésamo negro | O22: 150. Salep
E23: 61. Gin Tonic
E24: 62. Tom Collins
E25: 63. Whiskey Sour
E26: 64. Amaretto Sour
E27: 65. Paloma
E28: 66. Sidecar
E29: 67. French 75
E30: 68. Dark 'n' Stormy
E31: 69. Zombie
E32: 70. Singapore Sling
A36: Café = velocidad, rotación, productividad.
A37: Té = estabilidad, reducción de costes, sinergias regionales.
A38: Cócteles = efectos fuertes y condiciones especiales.
A39: Zumos = frescura, clientes, vegetarianos/veganos.
A40: Batidos = combos con postres, desayuno y platos dulces.
A41: Refrescos = comida rápida, volumen, platos baratos.
A42: Vinos y similares = lujo, carne, pasta, platos caros.

Sheet Region
B2: Region
B3: Mediterráneo
B4: Sudeste Asiático
B5: Caribe
B6: Balcanes
B7: Oriente Medio

Sheet País
B3: País
B4: Italia
B5: México
B6: Japón
B7: Perú

Sheet Tipo
B2: Tipo
B3: Pasta
B4: sopa
B5: arroz
B6: pizza
B7: bocadillo
B8: postre

Sheet Ingredientes
B3: Ingrtediente
B4: Carne
B5: pescado
B6: queso
B7: arroz
B8: patata

Sheet Estilo
B2: Estilo
B3: Callejero
B4: tradicional
B5: festivo
B6: alta cocina
B7: comida rápida

Sheet Carcteristica
B1: Para compartir | C1: Si en una misma mesa se repite un plato con esta etiqueta, aumenta su velocidad de cocina: 2 pedidos iguales → +20% 3 pedidos iguales → +30% 4 pedidos iguales → +40% Además, los platos Para compartir tienen más probabilidad de ser repetidos por otros clientes de la misma mesa: mesa de 2 → +20% mesa de 3 → +33% mesa de 4 → +50%.
B2: Crudo | C2: Aumenta un 5% la velocidad de cocina por cada plato Crudo que hay en la carta
B3: Picante | C3: Aumenta un 2% la velocidad de los camareros por cada plato con Picante que hay en la carta pero los clientes tienen un 2% menos de paciencia en mesa
B4: Frío | C4: Si toda la carta tiene platos fríos se cocinan un 30% mas rapido
B6: Sushi | C6: Si la carta contiene 4 o mas platos de sushi los clientes comen un 25% mas rapido y aumenta un 20% la aparicion de mas clientes
B7: Caldo/caldosos/sopas (nose como llamarlo) | C7: Si tienes 2 o mas platos con caldo en la carta los clientes tendran un 50% mas paciencia esperando en la mesa pero tardan 10% mas en cocinar/ Si tienes 4 platos sera 75% pero tardan 20% mas en cocinar
B8: Frito | C8: Si toda la carta tiene platos fritos aumenta un 50% la aparicion de clientes pero baja un 30% la tasa de aparicion de clientes vips
B9: Desayuno | C9: Si toda la carta tiene platos de desayuno el valor de los platos sube un 15%
B10: Comida Rapida | C10: Si tienes 3 o mas platos de comida rapida en la carta la cocina sube un 30% la velocidad de preparar platos
B11: "Gourmet" | C11: Si toda la carta tiene platos gourmet aumenta un 50% la aparicion de clientes vips pero baja un 50% la tasa de aparicion de clientes
B12: Vegetariano | C12: Si toda la carta es vegetariana sube la paciencia de la cola un 15% y la paciencia de las mesas 15% | Si en la misma carta existe platos con carne, pescado o marisco bajaran la aparicion de los clientes un 15%
B13: Vegano | C13: Si en la carta se encuentra 1 plato vegano sube el valor de los platos con vegetales un 5% | Si en la misma carta se encuentran 5 platos veganos sube el valor de los platos con vegetales un 15% | Si en la misma carta se encuentran los 10 platos veganos aumenta el valor de los platos vegetales un 30% y los vegetarianos un 10% pero baja un 15% la aparicion de mas clientes
... B31: Massa/harina/pan (nose como llamarlo) | C31: Si la carta contiene 2 platos o mas de massa sube el valor de los platos con massa un 15% / si tiene 6 platos o mas de massa sube el valor de los platos con massa un 25% / si tiene 10 platos o mas de massa sube el valor de los platos con massa un 50% y aumenta la velocida de cocina un 25%

Sheet Platos
D3: Plato | E3: Etiqueta 1 | F3: Etiqueta 2 | G3: Etiqueta 3 | H3: Etiqueta 4 | I3: Etiqueta 5 | J3: Etiqueta 6 | L3: PLATOS CORRECTOS
D4: Maki | E4: Sushi | F4: Arroz | G4: Pescado | H4: Frío | I4: Japonés | J4: — | L4: TRUE
D5: Sashimi | E5: Pescado | F5: Crudo | G5: Frío | H5: Japonés | I5: — | J5: — | L5: TRUE
D6: Onigiri | E6: Arroz | F6: Japonés | G6: — | H6: — | I6: — | J6: — | L6: TRUE
D7: Temaki | E7: Sushi | F7: Arroz | G7: Pescado | H7: Frío | I7: Japonés | J7: — | L7: TRUE
D8: Uramaki | E8: Sushi | F8: Arroz | G8: Pescado | H8: Frío | I8: Japonés | J8: — | L8: TRUE
D9: Gunkan | E9: Sushi | F9: Arroz | G9: Marisco | H9: Frío | I9: Japonés | J9: — | L9: TRUE
D10: Inari | E10: Sushi | F10: Arroz | G10: Vegetariano | H10: Japonés | I10: — | J10: — | L10: TRUE
D11: Nigiri | E11: Sushi | F11: Arroz | G11: Pescado | H11: Crudo | I11: Frío | J11: Japonés | L11: TRUE
D12: English breakfast | E12: Desayuno | F12: Carne | G12: Frito | H12: — | I12: — | J12: — | L12: TRUE
D13: Ceviche | E13: Peruano | F13: Pescado | G13: Marisco | H13: Crudo | I13: Frío | J13: Picante | L13: TRUE
D14: Falafel | E14: Frito | F14: Vegetales | G14: Vegetariano | H14: Vegano | I14: Comida rápida | J14: — | L14: TRUE
D15: Durum | E15: Carne | F15: Vegetales | G15: Comida rápida | H15: Masa | I15: — | J15: — | L15: FALSE
... D192: Jambalaya | E192: Estadounidense | F192: Arroz | G192: Marisco | H192: Carne | I192: Picante | J192: — | L192: TRUE

Sheet Recompte
B3: Sushi | D3: Arroz | F3: Pescado | H3: Frío | J3: Japonés | L3: Crudo
B4: =COUNTIF(Platos!E4:J483,Recompte!B3) -> 6 | D4: =COUNTIF(Platos!E4:J483,D3) -> 21 | F4: =COUNTIF(Platos!E4:J483,F3) -> 18 | H4: =COUNTIF(Platos!E4:J483,H3) -> 24 | J4: =COUNTIF(Platos!E4:J483,J3) -> 28 | L4: =COUNTIF(Platos!E4:J483,L3) -> 9
B6: Marisco | D6: Vegetariano | F6: Chino | H6: Desayuno | J6: Carne | L6: Frito
B7: =COUNTIF(Platos!E4:J483,B6) -> 23 | D7: =COUNTIF(Platos!E4:J483,D6) -> 46 | F7: =COUNTIF(Platos!E4:J483,F6) -> 18 | H7: =COUNTIF(Platos!E4:J483,H6) -> 15 | J7: =COUNTIF(Platos!E4:J483,J6) -> 70 | L7: =COUNTIF(Platos!E4:J483,L6) -> 25
B9: Peruano | D9: Picante | F9: Vegano | H9: Comida rápida | J9: Masa | L9: Patata
B10: =COUNTIF(Platos!E4:J483,B9) -> 18 | D10: =COUNTIF(Platos!E4:J483,D9) -> 26 | F10: =COUNTIF(Platos!E4:J483,F9) -> 14 | H10: =COUNTIF(Platos!E4:J483,H9) -> 35 | J10: =COUNTIF(Platos!E4:J483,J9) -> 55 | L10: =COUNTIF(Platos!E4:J483,L9) -> 16
B12: Español | D12: Para compartir | F12: Francés | H12: Mexicano | J12: Pasta/Fideos | L12: Caldo
B13: =COUNTIF(Platos!E4:J483,B12) -> 23 | D13: =COUNTIF(Platos!E4:J483,D12) -> 57 | F13: =COUNTIF(Platos!E4:J483,F12) -> 16 | H13: =COUNTIF(Platos!E4:J483,H12) -> 19 | J13: =COUNTIF(Platos!E4:J483,J12) -> 18 | L13: =COUNTIF(Platos!E4:J483,L12) -> 20
B15: Italiana | D15: Gourmet | F15: Estadounidense
B16: =COUNTIF(Platos!E4:J483,B15) -> 20 | D16: =COUNTIF(Platos!E4:J483,D15) -> 38 | F16: =COUNTIF(Platos!E4:J483,F15) -> 20

Sheet Platos Carac.
C2: PLATOS | D2: VALOR | E2: DURACION | F2: CARACT.
C3: Maki | D3: 4 | E3: 3
C4: Sashimi | D4: 8 | E4: 2
C5: Onigiri | D5: 3 | E5: 2
C6: Temaki | D6: 5 | E6: 3
C7: Uramaki | D7: 5 | E7: 3
C8: Gunkan | D8: 6 | E8: 3
C9: Inari | D9: 4 | E9: 2
C10: Nigiri | D10: 6 | E10: 3
C11: English breakfast | D11: 6 | E11: 5
C12: Ceviche | D12: 7 | E12: 4
C13: Falafel | D13: 3 | E13: 3
C14: Fish and chips | D14: 5 | E14: 4
... C141: Jambalaya | D141: 7 | E141: 6

Sheet Bebida
B1: Bebida | C1: Caract.
B2: Agua | C2: +2 % a los efectos de todas las etiquetas, según la regla que definas.
B3: Zumo naranja | C3: Aumenta un 10 % el valor de Desayuno y un 10 % la paciencia en mesa. Si toda la carta es Vegetariana, aumenta además un 10 % la llegada de clientes.
B4: Limonada | C4: Aumenta la velocidad de cocina de los platos Fríos un 15 %. Si tienes al menos 3 platos Picantes, elimina la penalización de paciencia de esa sinergia.
B5: Café con leche | C5: Aumenta el valor de Desayuno un 15 %. Si tienes 4 platos de Desayuno y 3 de Masa, los platos que tengan ambas etiquetas reciben un 15 % adicional de valor.
B6: Horchata | C6: Los platos Mexicanos y los de Arroz aumentan su valor un 10 %. Si hay al menos 3 de cada etiqueta, los platos que pertenezcan a ambas reciben otro 15 %
B7: Lassi de mango | C7: Aumenta un 15 % el valor de los platos Picantes. Si hay 5 platos Picantes, aumenta además un 15 % la velocidad de los camareros
B8: Batido de chocolate | C8: 30 % de valor a los platos de Desayuno.
B9: Refresco | C9: +15 % de valor a Comida rápida y +15 % de velocidad de camareros.
B10: Coctel internacional | C10: Si tiene como maximo 2 platos de sitios diferentes en la carta potenciara sus potenciadores un 10%, por ejemplo chino que potencia arroz un 4% si tiene los 2 maximos pues + 10 seria 14% y asi en cada region.
B11: Vino tinto
B12: Vino blanco
B13: Sangria
B14: Te verde | C14: China/Japon
B15: Sake
B16: Cerveza
B17: Chanpan
B18: Vino negro
B19: Vino rosado
B20: Tequila
B21: Granizado
B22: Café Americano
B23: Té de menta
B24: Mate
